Workbook

Sheet raw data
A1: Download Page | B1: H.8 Assets and Liabilities of Commercial Banks in the United States for Mar 18, 2022
A2: Series Description | B2: Bank credit, all commercial banks, seasonally adjusted | C2: Securities in bank credit, all commercial banks, seasonally adjusted | D2: Treasury and agency securities, all commercial banks, seasonally adjusted | E2: Treasury and agency securities: Mortgage-backed securities (MBS), all commercial banks, seasonally adjusted | F2: Treasury and agency securities: Non-MBS, all commercial banks, seasonally adjusted | G2: Other securities, all commercial banks, seasonally adjusted | H2: Other securities: Mortgage-backed securities, all commercial banks, seasonally adjusted | I2: Other securities: Non-MBS, all commercial banks, seasonally adjusted | J2: Loans and leases in bank credit, all commercial banks, seasonally adjusted | K2: Commercial and industrial loans, all commercial banks, seasonally adjusted | L2: Real estate loans, all commercial banks, seasonally adjusted | M2: Real estate loans: Residential real estate loans, all commercial banks, seasonally adjusted | N2: Real estate loans: Residential real estate loans: Revolving home equity loans, all commercial banks, seasonally adjusted | O2: Real estate loans: Residential real estate loans: Closed-end residential loans, all commercial banks, seasonally adjusted | P2: Real estate loans: Commercial real estate loans, all commercial banks, seasonally adjusted | Q2: Real estate loans: Commercial real estate loans: Construction and land development loans, all commercial banks, seasonally adjusted | R2: Real estate loans: Commercial real estate loans: Secured by farmland, all commercial banks, seasonally adjusted | S2: Real estate loans: Commercial real estate loans: Secured by multifamily properties, all commercial banks, seasonally adjusted | T2: Real estate loans: Commercial real estate loans: Secured by nonfarm nonresidential properties, all commercial banks, seasonally adjusted | U2: Consumer loans, all commercial banks, seasonally adjusted | V2: Consumer loans: Credit cards and other revolving plans, all commercial banks, seasonally adjusted | W2: Consumer loans: Other consumer loans, all commercial banks, seasonally adjusted | X2: Consumer loans: Other consumer loans: Automobile loans, all commercial banks, seasonally adjusted | Y2: Consumer loans: Other consumer loans: All other consumer loans, all commercial banks, seasonally adjusted | Z2: Other loans and leases: All other loans and leases, all commercial banks, seasonally adjusted | AA2: Other loans and leases: All other loans and leases: Loans to nondepository financial institutions, all commercial banks, seasonally adjusted | AB2: Other loans and leases: All other loans and leases: Other loans not elsewhere classified, all commercial banks, seasonally adjusted | AC2: LESS: Allowance for loan and lease losses, all commercial banks, seasonally adjusted | AD2: Cash assets, all commercial banks, seasonally adjusted | AE2: Federal funds sold and securities purchased under agreement to resell | AF2: Loans to commercial banks, all commercial banks, seasonally adjusted | AG2: Other assets, all commercial banks, seasonally adjusted | AH2: Total assets, all commercial banks, seasonally adjusted | AI2: Deposits, all commercial banks, seasonally adjusted | AJ2: Large time deposits, all commercial banks, seasonally adjusted | AK2: Other deposits, all commercial banks, seasonally adjusted | AL2: Borrowings, all commercial banks, seasonally adjusted | AM2: Net due to related foreign offices, all commercial banks, seasonally adjusted | AN2: Other liabilities, all commercial banks, seasonally adjusted | AO2: Total liabilities, all commercial banks, seasonally adjusted | AP2: Residual (assets less liabilities), all commercial banks, seasonally adjusted | AQ2: Net unrealized gains (losses) on available-for-sale securities, all commercial banks, seasonally adjusted | AR2: U.S. Treasury and agency securities, MBS, all commercial banks, seasonally adjusted | AS2: Total Deposits
A3: Unit: | B3: Currency | C3: Currency | D3: Currency | E3: Currency | F3: Currency | G3: Currency | H3: Currency | I3: Currency | J3: Currency | K3: Currency | L3: Currency | M3: Currency | N3: Currency | O3: Currency | P3: Currency | Q3: Currency | R3: Currency | S3: Currency | T3: Currency | U3: Currency | V3: Currency | W3: Currency | X3: Currency | Y3: Currency | Z3: Currency | AA3: Currency | AB3: Currency | AC3: Currency | AD3: Currency | AE3: Currency | AF3: Currency | AG3: Currency | AH3: Currency | AI3: Currency | AJ3: Currency | AK3: Currency | AL3: Currency | AM3: Currency | AN3: Currency | AO3: Currency | AP3: Currency | AQ3: Currency | AR3: Currency
A4: Multiplier: | B4: 1000000 | C4: 1000000 | D4: 1000000 | E4: 1000000 | F4: 1000000 | G4: 1000000 | H4: 1000000 | I4: 1000000 | J4: 1000000 | K4: 1000000 | L4: 1000000 | M4: 1000000 | N4: 1000000 | O4: 1000000 | P4: 1000000 | Q4: 1000000 | R4: 1000000 | S4: 1000000 | T4: 1000000 | U4: 1000000 | V4: 1000000 | W4: 1000000 | X4: 1000000 | Y4: 1000000 | Z4: 1000000 | AA4: 1000000 | AB4: 1000000 | AC4: 1000000 | AD4: 1000000 | AE4: 1000000 | AF4: 1000000 | AG4: 1000000 | AH4: 1000000 | AI4: 1000000 | AJ4: 1000000 | AK4: 1000000 | AL4: 1000000 | AM4: 1000000 | AN4: 1000000 | AO4: 1000000 | AP4: 1000000 | AQ4: 1000000 | AR4: 1000000
A5: Currency: | B5: USD | C5: USD | D5: USD | E5: USD | F5: USD | G5: USD | H5: USD | I5: USD | J5: USD | K5: USD | L5: USD | M5: USD | N5: USD | O5: USD | P5: USD | Q5: USD | R5: USD | S5: USD | T5: USD | U5: USD | V5: USD | W5: USD | X5: USD | Y5: USD | Z5: USD | AA5: USD | AB5: USD | AC5: USD | AD5: USD | AE5: USD | AF5: USD | AG5: USD | AH5: USD | AI5: USD | AJ5: USD | AK5: USD | AL5: USD | AM5: USD | AN5: USD | AO5: USD | AP5: USD | AQ5: USD | AR5: USD
A6: Unique Identifier: | B6: H8/H8/B1001NCBAM | C6: H8/H8/B1002NCBAM | D6: H8/H8/B1003NCBAM | E6: H8/H8/B1301NCBAM | F6: H8/H8/B1302NCBAM | G6: H8/H8/B1011NCBAM | H6: H8/H8/B1303NCBAM | I6: H8/H8/B1304NCBAM | J6: H8/H8/B1020NCBAM | K6: H8/H8/B1023NCBAM | L6: H8/H8/B1026NCBAM | M6: H8/H8/B1221NCBAM | N6: H8/H8/B1027NCBAM | O6: H8/H8/B1220NCBAM | P6: H8/H8/B3219NCBAM | Q6: H8/H8/B1215NCBAM | R6: H8/H8/B1216NCBAM | S6: H8/H8/B1217NCBAM | T6: H8/H8/B1218NCBAM | U6: H8/H8/B1029NCBAM | V6: H8/H8/B1247NCBAM | W6: H8/H8/B3248NCBAM | X6: H8/H8/B1243NCBAM | Y6: H8/H8/B1245NCBAM | Z6: H8/H8/B3305NCBAM | AA6: H8/H8/B1030NCBAM | AB6: H8/H8/B1310NCBAM | AC6: H8/H8/B1043NCBAM | AD6: H8/H8/B1048NCBAM | AE6: H8/H8/B3092NCBAM | AF6: H8/H8/B1047NCBAM | AG6: H8/H8/B3053NCBAM | AH6: H8/H8/B1151NCBAM | AI6: H8/H8/B1058NCBAM | AJ6: H8/H8/B1072NCBAM | AK6: H8/H8/B1110NCBAM | AL6: H8/H8/B3094NCBAM | AM6: H8/H8/B1100NCBAM | AN6: H8/H8/B3095NCBAM | AO6: H8/H8/B1152NCBAM | AP6: H8/H8/B1091NCBAM | AQ6: H8/H8/B1231NCBAM | AR6: H8/H8/B8321NCBAM
A7: Time Period | B7: B1001NCBAM | C7: B1002NCBAM | D7: B1003NCBAM | E7: B1301NCBAM | F7: B1302NCBAM | G7: B1011NCBAM | H7: B1303NCBAM | I7: B1304NCBAM | J7: B1020NCBAM | K7: B1023NCBAM | L7: B1026NCBAM | M7: B1221NCBAM | N7: B1027NCBAM | O7: B1220NCBAM | P7: B3219NCBAM | Q7: B1215NCBAM | R7: B1216NCBAM | S7: B1217NCBAM | T7: B1218NCBAM | U7: B1029NCBAM | V7: B1247NCBAM | W7: B3248NCBAM | X7: B1243NCBAM | Y7: B1245NCBAM | Z7: B3305NCBAM | AA7: B1030NCBAM | AB7: B1310NCBAM | AC7: B1043NCBAM | AD7: B1048NCBAM | AE7: B3092NCBAM | AF7: B1047NCBAM | AG7: B3053NCBAM | AH7: B1151NCBAM | AI7: B1058NCBAM | AJ7: B1072NCBAM | AK7: B1110NCBAM | AL7: B3094NCBAM | AM7: B1100NCBAM | AN7: B3095NCBAM | AO7: B1152NCBAM | AP7: B1091NCBAM | AQ7: B1231NCBAM | AR7: B8321NCBAM
A8: 1947-01 | B8: 109116.7 | C8: 82379.3 | D8: 74124.7 | G8: 8254.5 | J8: 26737.5 | K8: 11289.4 | L8: 6796 | U8: 4161.2
A9: 1947-02 | B9: 108530.3 | C9: 81273.4 | D9: 73208 | G9: 8065.4 | J9: 27257 | K9: 11517.9 | L9: 6955.1 | U9: 4296.6
A10: 1947-03 | B10: 108370.6 | C10: 80565.3 | D10: 72498.3 | G10: 8067 | J10: 27805.4 | K10: 11766.7 | L10: 7124.9 | U10: 4430.6
A11: 1947-04 | B11: 108560.8 | C11: 80189.4 | D11: 72226.4 | G11: 7962.9 | J11: 28371.4 | K11: 12026.9 | L11: 7296.6 | U11: 4568.7
A12: 1947-05 | B12: 108539 | C12: 79606.7 | D12: 71902.1 | G12: 7704.6 | J12: 28932.2 | K12: 12278.8 | L12: 7469.9 | U12: 4708.7
A13: 1947-06 | B13: 108459.4 | C13: 78854.3 | D13: 71414 | G13: 7440.4 | J13: 29605 | K13: 12483.2 | L13: 7636.1 | U13: 4846.5
A14: 1947-07 | B14: 108747.5 | C14: 77749.5 | D14: 71104.8 | G14: 6644.7 | J14: 30998 | K14: 12780 | L14: 7809.2 | U14: 4981.5
A15: 1947-08 | B15: 109045.3 | C15: 77544.9 | D15: 70835.5 | G15: 6709.5 | J15: 31500.4 | K15: 13082.2 | L15: 7980.9 | U15: 5116.8
A16: 1947-09 | B16: 109921.9 | C16: 77952.7 | D16: 71156.5 | G16: 6796.1 | J16: 31969.2 | K16: 13352.3 | L16: 8148.7 | U16: 5248.4
A17: 1947-10 | B17: 110375.5 | C17: 77936.5 | D17: 71101.5 | G17: 6835 | J17: 32439 | K17: 13628.7 | L17: 8317.4 | U17: 5381.9
A18: 1947-11 | B18: 110432.6 | C18: 77541.6 | D18: 70724.6 | G18: 6817 | J18: 32891.1 | K18: 13899.8 | L18: 8484.5 | U18: 5514.2
A19: 1947-12 | B19: 110296.7 | C19: 76921.3 | D19: 70083.3 | G19: 6837.9 | J19: 33375.4 | K19: 14205.3 | L19: 8642.8 | U19: 5645.6
... A319: 1972-12 | B319: 560125.1 | C319: 159746.8 | D319: 86939.3 | G319: 72807.5 | J319: 400378.3 | K319: 133109.3 | L319: 96869.5 | U319: 85260.1
A320: 1973-01 | B320: 566513.4 | C320: 161359.5 | D320: 89971.8 | G320: 71387.7 | J320: 405153.9 | K320: 135413.5 | L320: 98701.1 | U320: 86477.4 | Z320: 84561.9 | AD320: 84468.7 | AF320: 3621.2 | AG320: 29552.4 | AH320: 702318.8 | AI320: 596878.7 | AJ320: 94393.3 | AL320: 7546.4 | AN320: 21037.2 | AO320: 626069.9 | AP320: 76248.9 | AS320: =SUM(AI320:AK320) -> 691272 | AT320: =AH320/AS320 -> 1.0159804
A321: 1973-02 | B321: 574254.8 | C321: 158635.2 | D321: 86578.8 | G321: 72056.5 | J321: 415619.6 | K321: 140798.3 | L321: 100456.1 | U321: 88258.7 | Z321: 86106.5 | AD321: 83623.6 | AF321: 3950.2 | AG321: 30689.6 | AH321: 710763.2 | AI321: 598920.7 | AJ321: 97452.2 | AL321: 9121.3 | AN321: 21832.7 | AO321: 629659.8 | AP321: 81103.4 | AS321: =SUM(AI321:AK321) -> 696372.9 | AT321: =AH321/AS321 -> 1.0206646
A322: 1973-03 | B322: 584043.9 | C322: 158098.1 | D322: 85320.9 | G322: 72777.2 | J322: 425945.8 | K322: 144957.6 | L322: 102460.6 | U322: 89855.5 | Z322: 88672.2 | AD322: 81888.4 | AF322: 4321.4 | AG322: 31653.3 | AH322: 719914 | AI322: 602988.9 | AJ322: 101766.9 | AL322: 10524.6 | AN322: 22585.4 | AO322: 635251.7 | AP322: 84662.2 | AS322: =SUM(AI322:AK322) -> 704755.8 | AT322: =AH322/AS322 -> 1.0215084
A323: 1973-04 | B323: 590109 | C323: 158342.5 | D323: 85348.2 | G323: 72994.2 | J323: 431766.5 | K323: 147534.3 | L323: 104303.2 | U323: 91127.8 | Z323: 88801.3 | AD323: 83097.8 | AF323: 4343.4 | AG323: 32503 | AH323: 728455.9 | AI323: 612431.7 | AJ323: 104024.9 | AL323: 10693.7 | AN323: 23314 | AO323: 645630.4 | AP323: 82825.5 | AS323: =SUM(AI323:AK323) -> 716456.6 | AT323: =AH323/AS323 -> 1.0167481
A324: 1973-05 | B324: 595891.1 | C324: 157084.2 | D324: 83157 | G324: 73927.2 | J324: 438806.8 | K324: 149965.9 | L324: 105816.3 | U324: 92158.8 | Z324: 90865.8 | AD324: 84324.9 | AF324: 4809.6 | AG324: 32864.4 | AH324: 737316.4 | AI324: 614374.1 | AJ324: 106421.6 | AL324: 11464.4 | AN324: 24319.9 | AO324: 649692.4 | AP324: 87624 | AS324: =SUM(AI324:AK324) -> 720795.7 | AT324: =AH324/AS324 -> 1.0229201
A325: 1973-06 | B325: 603759 | C325: 157686.5 | D325: 83142.7 | G325: 74543.7 | J325: 446072.6 | K325: 152829.2 | L325: 107511.3 | U325: 93248.6 | Z325: 92483.4 | AD325: 85793.4 | AF325: 5083.6 | AG325: 33553.4 | AH325: 748128 | AI325: 623141.1 | AJ325: 107138.9 | AL325: 12303.6 | AN325: 24523.7 | AO325: 659303.2 | AP325: 88824.8 | AS325: =SUM(AI325:AK325) -> 730280 | AT325: =AH325/AS325 -> 1.0244399
A326: 1973-07 | B326: 610141.6 | C326: 157329.7 | D326: 82198.5 | G326: 75131.2 | J326: 452811.9 | K326: 155329.1 | L326: 109238.7 | U326: 94325.2 | Z326: 93918.9 | AD326: 88236.9 | AF326: 5374.3 | AG326: 33806.1 | AH326: 758057.8 | AI326: 630928.1 | AJ326: 109100.7 | AL326: 13618.1 | AN326: 24269.9 | AO326: 667897.9 | AP326: 90159.9 | AS326: =SUM(AI326:AK326) -> 740028.8 | AT326: =AH326/AS326 -> 1.0243626
A327: 1973-08 | B327: 616517.2 | C327: 157733.2 | D327: 81396.5 | G327: 76336.7 | J327: 458784 | K327: 158068.1 | L327: 110902.4 | U327: 95283.3 | Z327: 94530.2 | AD327: 86650.1 | AF327: 5240 | AG327: 35037.3 | AH327: 764744.3 | AI327: 629977.3 | AJ327: 113785.8 | AL327: 14378.5 | AN327: 25014.7 | AO327: 668182 | AP327: 96562.3 | AS327: =SUM(AI327:AK327) -> 743763.1 | AT327: =AH327/AS327 -> 1.0282095
A328: 1973-09 | B328: 621387 | C328: 159393.2 | D328: 82381.2 | G328: 77012 | J328: 461993.8 | K328: 158506.6 | L328: 112484.8 | U328: 96007.2 | Z328: 94995.2 | AD328: 88681.5 | AF328: 5114.6 | AG328: 35474.1 | AH328: 771226.5 | AI328: 638646.4 | AJ328: 115221 | AL328: 14515.2 | AN328: 24948 | AO328: 676638.4 | AP328: 94588.1 | AS328: =SUM(AI328:AK328) -> 753867.4 | AT328: =AH328/AS328 -> 1.0230267
A329: 1973-10 | B329: 625568.1 | C329: 161086.2 | D329: 83565.1 | G329: 77521.1 | J329: 464481.9 | K329: 159169.4 | L329: 113968.4 | U329: 96788.9 | Z329: 94555.3 | AD329: 91244 | AF329: 5281.7 | AG329: 36207.8 | AH329: 780241.8 | AI329: 647617.9 | AJ329: 115092.4 | AL329: 14398.6 | AN329: 25140.9 | AO329: 685556.2 | AP329: 94685.6 | AS329: =SUM(AI329:AK329) -> 762710.3 | AT329: =AH329/AS329 -> 1.0229858
A330: 1973-11 | B330: 631539.8 | C330: 164213.8 | D330: 87719.5 | G330: 76494.2 | J330: 467326 | K330: 159935.3 | L330: 115531.3 | U330: 97775.8 | Z330: 94083.6 | AD330: 92072 | AF330: 5644.1 | AG330: 36148.4 | AH330: 787258.3 | AI330: 649140.6 | AJ330: 113958.4 | AL330: 14423.7 | AN330: 26196.7 | AO330: 688511.1 | AP330: 98747.2 | AS330: =SUM(AI330:AK330) -> 763099 | AT330: =AH330/AS330 -> 1.0316595
A331: 1973-12 | B331: 641131.5 | C331: 166904.5 | D331: 90078.2 | G331: 76826.2 | J331: 474227 | K331: 161211.3 | L331: 117002 | U331: 98350.7 | Z331: 97663.1 | AD331: 91904.9 | AF331: 5631.9 | AG331: 36616.8 | AH331: 798083.8 | AI331: 663699.3 | AJ331: 115016.2 | AL331: 14896.6 | AN331: 26343.1 | AO331: 703335 | AP331: 94748.7 | AS331: =SUM(AI331:AK331) -> 778715.5 | AT331: =AH331/AS331 -> 1.0248721
... A493: 1987-06 | B493: 2128263.7 | C493: 512794.9 | D493: 319570.8 | G493: 193224.1 | J493: 1615468.8 | K493: 554536.4 | L493: 541734.6 | U493: 315461 | Z493: 203736.8 | AD493: 239098.2 | AF493: 46455.6 | AG493: 154025.4 | AH493: 2679452.5 | AI493: 1956094.5 | AJ493: 374940.2 | AL493: 400781.4 | AN493: 150118.6 | AO493: 2496445.3 | AP493: 183007.2 | AS493: =SUM(AI493:AK493) -> 2331034.7 | AT493: =AH493/AS493 -> 1.1494692
A494: 1987-07 | B494: 2134064.1 | C494: 514631 | D494: 322413.1 | G494: 192217.9 | J494: 1619433.1 | K494: 553429.3 | L494: 549405 | N494: 24996.2 | U494: 316961.3 | Z494: 199637.5 | AD494: 232366.3 | AF494: 46905.2 | AG494: 156180.7 | AH494: 2675367.4 | AI494: 1955520.6 | AJ494: 376907.5 | AL494: 400944.6 | AN494: 146504.1 | AO494: 2496579.9 | AP494: 178787.5 | AS494: =SUM(AI494:AK494) -> 2332428.1 | AT494: =AH494/AS494 -> 1.147031
A495: 1987-08 | B495: 2145622.3 | C495: 517365 | D495: 326585.4 | G495: 190779.7 | J495: 1628257.3 | K495: 554134.1 | L495: 556232.1 | N495: 26179 | U495: 319344.3 | Z495: 198546.8 | AD495: 234014.5 | AF495: 44887 | AG495: 157279.8 | AH495: 2691966.6 | AI495: 1961994.3 | AJ495: 377261.6 | AL495: 406575.1 | AN495: 145977.2 | AO495: 2514874.4 | AP495: 177092.3 | AS495: =SUM(AI495:AK495) -> 2339255.9 | AT495: =AH495/AS495 -> 1.150779
A496: 1987-09 | B496: 2168390.3 | C496: 520434.8 | D496: 329523.6 | G496: 190911.2 | J496: 1647955.5 | K496: 561315.8 | L496: 563145.4 | N496: 27441.6 | U496: 321890.1 | Z496: 201604.3 | AD496: 235208.6 | AF496: 45121.5 | AG496: 161969.4 | AH496: 2720042.6 | AI496: 1967775.6 | AJ496: 378173.9 | AL496: 405264.6 | AN496: 149489.4 | AO496: 2534488.5 | AP496: 185554.1 | AS496: =SUM(AI496:AK496) -> 2345949.5 | AT496: =AH496/AS496 -> 1.1594634
A497: 1987-10 | B497: 2181092.1 | C497: 519795.9 | D497: 329945.4 | G497: 189850.5 | J497: 1661296.2 | K497: 563135.2 | L497: 570786.1 | N497: 28478.9 | U497: 324308.8 | Z497: 203066.1 | AD497: 233999.9 | AF497: 45307.2 | AG497: 165501.1 | AH497: 2742921.4 | AI497: 1980899.9 | AJ497: 385908.6 | AL497: 410041.8 | AN497: 155010.1 | AO497: 2554330.5 | AP497: 188591 | AS497: =SUM(AI497:AK497) -> 2366808.5 | AT497: =AH497/AS497 -> 1.1589114
A498: 1987-11 | B498: 2184679.4 | C498: 521498 | D498: 331409.5 | G498: 190088.5 | J498: 1663181.3 | K498: 562499.9 | L498: 577697.8 | N498: 29577.2 | U498: 325035.2 | Z498: 197948.5 | AD498: 230357.7 | AF498: 45251 | AG498: 164366.3 | AH498: 2733486 | AI498: 1984034.6 | AJ498: 392363.3 | AL498: 409656.4 | AN498: 152460.8 | AO498: 2552006.7 | AP498: 181479.3 | AS498: =SUM(AI498:AK498) -> 2376397.9 | AT498: =AH498/AS498 -> 1.1502644
A499: 1987-12 | B499: 2198307.5 | C499: 525111.3 | D499: 335150.1 | G499: 189961.2 | J499: 1673196.2 | K499: 564982.8 | L499: 585701.5 | N499: 30624.4 | U499: 326865.4 | Z499: 195646.5 | AD499: 228877.7 | AF499: 44573.3 | AG499: 160188.6 | AH499: 2734023.8 | AI499: 1985596.9 | AJ499: 394750.9 | AL499: 408635.6 | AN499: 151938.9 | AO499: 2555242.6 | AP499: 178781.2 | AS499: =SUM(AI499:AK499) -> 2380347.8 | AT499: =AH499/AS499 -> 1.1485816
A500: 1988-01 | B500: 2212630 | C500: 527214.5 | D500: 335251.9 | G500: 191962.6 | J500: 1685415.5 | K500: 567074.6 | L500: 591581 | N500: 31826.6 | U500: 330265.8 | Z500: 196494.2 | AD500: 234979 | AF500: 44104.5 | AG500: 154988.2 | AH500: 2751583.2 | AI500: 2000534.2 | AJ500: 397004.7 | AL500: 417718.3 | AN500: 149398.7 | AO500: 2575012.3 | AP500: 176570.9 | AS500: =SUM(AI500:AK500) -> 2397538.9 | AT500: =AH500/AS500 -> 1.1476699
...

Sheet results
A1: Time | C1: Credit Card | D1: Other Asset | E1: Total Asset | F1: Total Liability | G1: Total Deposits | H1: Residual (NW) | I1: Residual (NW) - D | J1: CC / TA | K1: OA / CC | L1: TA / CC | M1: TL / CC | N1: TA / TL | O1: TA / NW
A2: ='raw data'!A650 -> 2000-07 | B2: ='raw data'!U650 -> 531142 | C2: ='raw data'!V650 -> 211897.8 | D2: =E2-C2 -> 5693184 | E2: ='raw data'!AH650 -> 5905081.8 | F2: ='raw data'!AO650 -> 5678886 | G2: ='raw data'!AS650 -> 4521704.5 | H2: =E2-F2 -> 226195.8 | I2: =E2-G2 -> 1383377.3 | J2: =C2/E2*100 -> 3.5883974 | K2: =D2/C2 -> 26.867594 | L2: =E2/C2 -> 27.867594 | M2: =F2/C2 -> 26.800118 | N2: =E2/F2 -> 1.039831 | O2: =E2/H2 -> 26.106063 | P2: =E2/I2 -> 4.2685982
A3: ='raw data'!A651 -> 2000-08 | B3: ='raw data'!U651 -> 538855.4 | C3: ='raw data'!V651 -> 217854 | D3: =E3-C3 -> 5716299.2 | E3: ='raw data'!AH651 -> 5934153.2 | F3: ='raw data'!AO651 -> 5714051.1 | G3: ='raw data'!AS651 -> 4564306.7 | H3: =E3-F3 -> 220102.1 | I3: =E3-G3 -> 1369846.5 | J3: =C3/E3*100 -> 3.6711893 | K3: =D3/C3 -> 26.239129 | L3: =E3/C3 -> 27.239129 | M3: =F3/C3 -> 26.22881 | N3: =E3/F3 -> 1.0385194 | O3: =E3/H3 -> 26.960911 | P3: =E3/I3 -> 4.3319841
A4: ='raw data'!A652 -> 2000-09 | B4: ='raw data'!U652 -> 543717.1 | C4: ='raw data'!V652 -> 222410.9 | D4: =E4-C4 -> 5751305.6 | E4: ='raw data'!AH652 -> 5973716.5 | F4: ='raw data'!AO652 -> 5736376.6 | G4: ='raw data'!AS652 -> 4578304.4 | H4: =E4-F4 -> 237339.9 | I4: =E4-G4 -> 1395412.1 | J4: =C4/E4*100 -> 3.7231579 | K4: =D4/C4 -> 25.85892 | L4: =E4/C4 -> 26.85892 | M4: =F4/C4 -> 25.791796 | N4: =E4/F4 -> 1.0413745 | O4: =E4/H4 -> 25.169457 | P4: =E4/I4 -> 4.2809694
A5: ='raw data'!A653 -> 2000-10 | B5: ='raw data'!U653 -> 544271.9 | C5: ='raw data'!V653 -> 220752.4 | D5: =E5-C5 -> 5770217.5 | E5: ='raw data'!AH653 -> 5990969.9 | F5: ='raw data'!AO653 -> 5730192.1 | G5: ='raw data'!AS653 -> 4585167.3 | H5: =E5-F5 -> 260777.8 | I5: =E5-G5 -> 1405802.6 | J5: =C5/E5*100 -> 3.6847523 | K5: =D5/C5 -> 26.138866 | L5: =E5/C5 -> 27.138866 | M5: =F5/C5 -> 25.957553 | N5: =E5/F5 -> 1.0455094 | O5: =E5/H5 -> 22.973466 | P5: =E5/I5 -> 4.2616011
A6: ='raw data'!A654 -> 2000-11 | B6: ='raw data'!U654 -> 548263.8 | C6: ='raw data'!V654 -> 222338.7 | D6: =E6-C6 -> 5768300.6 | E6: ='raw data'!AH654 -> 5990639.3 | F6: ='raw data'!AO654 -> 5716039.2 | G6: ='raw data'!AS654 -> 4576630.5 | H6: =E6-F6 -> 274600.1 | I6: =E6-G6 -> 1414008.8 | J6: =C6/E6*100 -> 3.7114353 | K6: =D6/C6 -> 25.943754 | L6: =E6/C6 -> 26.943754 | M6: =F6/C6 -> 25.708701 | N6: =E6/F6 -> 1.0480403 | O6: =E6/H6 -> 21.815867 | P6: =E6/I6 -> 4.2366351
A7: ='raw data'!A655 -> 2000-12 | B7: ='raw data'!U655 -> 555531.4 | C7: ='raw data'!V655 -> 228197.3 | D7: =E7-C7 -> 5839338.5 | E7: ='raw data'!AH655 -> 6067535.8 | F7: ='raw data'!AO655 -> 5809431.8 | G7: ='raw data'!AS655 -> 4646582.5 | H7: =E7-F7 -> 258104 | I7: =E7-G7 -> 1420953.3 | J7: =C7/E7*100 -> 3.7609551 | K7: =D7/C7 -> 25.58899 | L7: =E7/C7 -> 26.58899 | M7: =F7/C7 -> 25.457934 | N7: =E7/F7 -> 1.0444284 | O7: =E7/H7 -> 23.508104 | P7: =E7/I7 -> 4.2700459
A8: ='raw data'!A656 -> 2001-01 | B8: ='raw data'!U656 -> 558590.1 | C8: ='raw data'!V656 -> 230967.4 | D8: =E8-C8 -> 5920051.7 | E8: ='raw data'!AH656 -> 6151019.1 | F8: ='raw data'!AO656 -> 5877247 | G8: ='raw data'!AS656 -> 4688421.9 | H8: =E8-F8 -> 273772.1 | I8: =E8-G8 -> 1462597.2 | J8: =C8/E8*100 -> 3.7549453 | K8: =D8/C8 -> 25.631547 | L8: =E8/C8 -> 26.631547 | M8: =F8/C8 -> 25.446219 | N8: =E8/F8 -> 1.0465817 | O8: =E8/H8 -> 22.467662 | P8: =E8/I8 -> 4.2055455
A9: ='raw data'!A657 -> 2001-02 | B9: ='raw data'!U657 -> 557858 | C9: ='raw data'!V657 -> 229551.1 | D9: =E9-C9 -> 5908417.3 | E9: ='raw data'!AH657 -> 6137968.4 | F9: ='raw data'!AO657 -> 5870782.7 | G9: ='raw data'!AS657 -> 4700436.3 | H9: =E9-F9 -> 267185.7 | I9: =E9-G9 -> 1437532.1 | J9: =C9/E9*100 -> 3.7398547 | K9: =D9/C9 -> 25.739007 | L9: =E9/C9 -> 26.739007 | M9: =F9/C9 -> 25.575058 | N9: =E9/F9 -> 1.0455111 | O9: =E9/H9 -> 22.972668 | P9: =E9/I9 -> 4.2697957
A10: ='raw data'!A658 -> 2001-03 | B10: ='raw data'!U658 -> 557205.5 | C10: ='raw data'!V658 -> 228144.8 | D10: =E10-C10 -> 5960646.7 | E10: ='raw data'!AH658 -> 6188791.5 | F10: ='raw data'!AO658 -> 5919212.6 | G10: ='raw data'!AS658 -> 4737073.4 | H10: =E10-F10 -> 269578.9 | I10: =E10-G10 -> 1451718.1 | J10: =C10/E10*100 -> 3.6864192 | K10: =D10/C10 -> 26.126595 | L10: =E10/C10 -> 27.126595 | M10: =F10/C10 -> 25.944981 | N10: =E10/F10 -> 1.045543 | O10: =E10/H10 -> 22.957255 | P10: =E10/I10 -> 4.2630808
A11: ='raw data'!A659 -> 2001-04 | B11: ='raw data'!U659 -> 561350.2 | C11: ='raw data'!V659 -> 232200.8 | D11: =E11-C11 -> 5996841.9 | E11: ='raw data'!AH659 -> 6229042.7 | F11: ='raw data'!AO659 -> 5948783.7 | G11: ='raw data'!AS659 -> 4783168.3 | H11: =E11-F11 -> 280259 | I11: =E11-G11 -> 1445874.4 | J11: =C11/E11*100 -> 3.7277124 | K11: =D11/C11 -> 25.826104 | L11: =E11/C11 -> 26.826104 | M11: =F11/C11 -> 25.619135 | N11: =E11/F11 -> 1.047112 | O11: =E11/H11 -> 22.226022 | P11: =E11/I11 -> 4.3081492
A12: ='raw data'!A660 -> 2001-05 | B12: ='raw data'!U660 -> 566114.6 | C12: ='raw data'!V660 -> 235574.1 | D12: =E12-C12 -> 5983711.3 | E12: ='raw data'!AH660 -> 6219285.4 | F12: ='raw data'!AO660 -> 5946266.5 | G12: ='raw data'!AS660 -> 4814665.4 | H12: =E12-F12 -> 273018.9 | I12: =E12-G12 -> 1404620 | J12: =C12/E12*100 -> 3.7878001 | K12: =D12/C12 -> 25.400548 | L12: =E12/C12 -> 26.400548 | M12: =F12/C12 -> 25.241597 | N12: =E12/F12 -> 1.0459143 | O12: =E12/H12 -> 22.779688 | P12: =E12/I12 -> 4.4277352
A13: ='raw data'!A661 -> 2001-06 | B13: ='raw data'!U661 -> 564557.4 | C13: ='raw data'!V661 -> 233267.1 | D13: =E13-C13 -> 5974287.5 | E13: ='raw data'!AH661 -> 6207554.6 | F13: ='raw data'!AO661 -> 5932611.4 | G13: ='raw data'!AS661 -> 4833647.1 | H13: =E13-F13 -> 274943.2 | I13: =E13-G13 -> 1373907.5 | J13: =C13/E13*100 -> 3.7577938 | K13: =D13/C13 -> 25.611359 | L13: =E13/C13 -> 26.611359 | M13: =F13/C13 -> 25.432697 | N13: =E13/F13 -> 1.0463444 | O13: =E13/H13 -> 22.577589 | P13: =E13/I13 -> 4.5181751
... A43: ='raw data'!A691 -> 2003-12 | B43: ='raw data'!U691 -> 664772.1 | C43: ='raw data'!V691 -> 280989.7 | D43: =E43-C43 -> 7033550.5 | E43: ='raw data'!AH691 -> 7314540.2 | F43: ='raw data'!AO691 -> 6930551.9 | G43: ='raw data'!AS691 -> 5631953.6 | H43: =E43-F43 -> 383988.3 | I43: =E43-G43 -> 1682586.6 | J43: =C43/E43*100 -> 3.8415224 | K43: =D43/C43 -> 25.031346 | L43: =E43/C43 -> 26.031346 | M43: =F43/C43 -> 24.66479 | N43: =E43/F43 -> 1.0554052 | O43: =E43/H43 -> 19.048862 | P43: =E43/I43 -> 4.3471998
A44: ='raw data'!A692 -> 2004-01 | B44: ='raw data'!U692 -> 671934.4 | C44: ='raw data'!V692 -> 283276.6 | D44: =E44-C44 -> 7118876.4 | E44: ='raw data'!AH692 -> 7402153 | F44: ='raw data'!AO692 -> 7023084 | G44: ='raw data'!AS692 -> 5684357.4 | H44: =E44-F44 -> 379069 | I44: =E44-G44 -> 1717795.6 | J44: =C44/E44*100 -> 3.8269487 | K44: =D44/C44 -> 25.130478 | L44: =E44/C44 -> 26.130478 | M44: =F44/C44 -> 24.79232 | N44: =E44/F44 -> 1.0539747 | O44: =E44/H44 -> 19.527192 | P44: =E44/I44 -> 4.3091 | Q44: Avg CC/TA
A45: ='raw data'!A693 -> 2004-02 | B45: ='raw data'!U693 -> 671297.8 | C45: ='raw data'!V693 -> 281560.2 | D45: =E45-C45 -> 7239054.6 | E45: ='raw data'!AH693 -> 7520614.8 | F45: ='raw data'!AO693 -> 7130441.1 | G45: ='raw data'!AS693 -> 5749278.9 | H45: =E45-F45 -> 390173.7 | I45: =E45-G45 -> 1771335.9 | J45: =C45/E45*100 -> 3.7438455 | K45: =D45/C45 -> 25.710504 | L45: =E45/C45 -> 26.710504 | M45: =F45/C45 -> 25.324748 | N45: =E45/F45 -> 1.0547194 | O45: =E45/H45 -> 19.275043 | P45: =E45/I45 -> 4.2457305 | Q45: =AVERAGE(J44:J55) -> 3.6979737
A46: ='raw data'!A694 -> 2004-03 | B46: ='raw data'!U694 -> 669655.6 | C46: ='raw data'!V694 -> 279474.5 | D46: =E46-C46 -> 7272080.8 | E46: ='raw data'!AH694 -> 7551555.3 | F46: ='raw data'!AO694 -> 7160907.1 | G46: ='raw data'!AS694 -> 5828558.8 | H46: =E46-F46 -> 390648.2 | I46: =E46-G46 -> 1722996.5 | J46: =C46/E46*100 -> 3.7008866 | K46: =D46/C46 -> 26.020552 | L46: =E46/C46 -> 27.020552 | M46: =F46/C46 -> 25.622757 | N46: =E46/F46 -> 1.0545529 | O46: =E46/H46 -> 19.330833 | P46: =E46/I46 -> 4.3828036 | Q46: Avg TA/NW
A47: ='raw data'!A695 -> 2004-04 | B47: ='raw data'!U695 -> 672082.9 | C47: ='raw data'!V695 -> 281049.1 | D47: =E47-C47 -> 7357249.4 | E47: ='raw data'!AH695 -> 7638298.5 | F47: ='raw data'!AO695 -> 7202602.1 | G47: ='raw data'!AS695 -> 5891009 | H47: =E47-F47 -> 435696.4 | I47: =E47-G47 -> 1747289.5 | J47: =C47/E47*100 -> 3.6794726 | K47: =D47/C47 -> 26.177808 | L47: =E47/C47 -> 27.177808 | M47: =F47/C47 -> 25.627558 | N47: =E47/F47 -> 1.0604915 | O47: =E47/H47 -> 17.531241 | P47: =E47/I47 -> 4.3715128 | Q47: =AVERAGE(O44:O55) -> 18.060952
A48: ='raw data'!A696 -> 2004-05 | B48: ='raw data'!U696 -> 677176.8 | C48: ='raw data'!V696 -> 284903.9 | D48: =E48-C48 -> 7379888.4 | E48: ='raw data'!AH696 -> 7664792.3 | F48: ='raw data'!AO696 -> 7233687.2 | G48: ='raw data'!AS696 -> 6000669.7 | H48: =E48-F48 -> 431105.1 | I48: =E48-G48 -> 1664122.6 | J48: =C48/E48*100 -> 3.7170466 | K48: =D48/C48 -> 25.90308 | L48: =E48/C48 -> 26.90308 | M48: =F48/C48 -> 25.38992 | N48: =E48/F48 -> 1.0595969 | O48: =E48/H48 -> 17.779405 | P48: =E48/I48 -> 4.605906 | Q48: Avg OA/CC
A49: ='raw data'!A697 -> 2004-06 | B49: ='raw data'!U697 -> 679977.5 | C49: ='raw data'!V697 -> 287433.6 | D49: =E49-C49 -> 7454905.4 | E49: ='raw data'!AH697 -> 7742339 | F49: ='raw data'!AO697 -> 7331544.1 | G49: ='raw data'!AS697 -> 6060581.5 | H49: =E49-F49 -> 410794.9 | I49: =E49-G49 -> 1681757.5 | J49: =C49/E49*100 -> 3.7124905 | K49: =D49/C49 -> 25.936096 | L49: =E49/C49 -> 26.936096 | M49: =F49/C49 -> 25.506914 | N49: =E49/F49 -> 1.0560312 | O49: =E49/H49 -> 18.847213 | P49: =E49/I49 -> 4.603719 | Q49: =AVERAGE(K44:K55) -> 26.047342
A50: ='raw data'!A698 -> 2004-07 | B50: ='raw data'!U698 -> 680087 | C50: ='raw data'!V698 -> 287878.6 | D50: =E50-C50 -> 7557867.1 | E50: ='raw data'!AH698 -> 7845745.7 | F50: ='raw data'!AO698 -> 7433368.8 | G50: ='raw data'!AS698 -> 6156965.3 | H50: =E50-F50 -> 412376.9 | I50: =E50-G50 -> 1688780.4 | J50: =C50/E50*100 -> 3.6692318 | K50: =D50/C50 -> 26.253661 | L50: =E50/C50 -> 27.253661 | M50: =F50/C50 -> 25.821193 | N50: =E50/F50 -> 1.0554764 | O50: =E50/H50 -> 19.025667 | P50: =E50/I50 -> 4.6458058 | Q50: Avg TA/TL
A51: ='raw data'!A699 -> 2004-08 | B51: ='raw data'!U699 -> 683613.5 | C51: ='raw data'!V699 -> 290661.3 | D51: =E51-C51 -> 7586471.1 | E51: ='raw data'!AH699 -> 7877132.4 | F51: ='raw data'!AO699 -> 7445370.8 | G51: ='raw data'!AS699 -> 6169053.8 | H51: =E51-F51 -> 431761.6 | I51: =E51-G51 -> 1708078.6 | J51: =C51/E51*100 -> 3.689938 | K51: =D51/C51 -> 26.100727 | L51: =E51/C51 -> 27.100727 | M51: =F51/C51 -> 25.615281 | N51: =E51/F51 -> 1.0579906 | O51: =E51/H51 -> 18.244171 | P51: =E51/I51 -> 4.611692 | Q51: =AVERAGE(N44:N55) -> 1.0588514
A52: ='raw data'!A700 -> 2004-09 | B52: ='raw data'!U700 -> 686419.5 | C52: ='raw data'!V700 -> 294299.2 | D52: =E52-C52 -> 7666584.1 | E52: ='raw data'!AH700 -> 7960883.3 | F52: ='raw data'!AO700 -> 7498189.3 | G52: ='raw data'!AS700 -> 6202452.8 | H52: =E52-F52 -> 462694 | I52: =E52-G52 -> 1758430.5 | J52: =C52/E52*100 -> 3.6968159 | K52: =D52/C52 -> 26.050306 | L52: =E52/C52 -> 27.050306 | M52: =F52/C52 -> 25.478116 | N52: =E52/F52 -> 1.0617074 | O52: =E52/H52 -> 17.205504 | P52: =E52/I52 -> 4.5272664 | Q52: Avg TL/CC
A53: ='raw data'!A701 -> 2004-10 | B53: ='raw data'!U701 -> 684346.8 | C53: ='raw data'!V701 -> 291309 | D53: =E53-C53 -> 7682430.6 | E53: ='raw data'!AH701 -> 7973739.6 | F53: ='raw data'!AO701 -> 7493249 | G53: ='raw data'!AS701 -> 6241305.6 | H53: =E53-F53 -> 480490.6 | I53: =E53-G53 -> 1732434 | J53: =C53/E53*100 -> 3.6533548 | K53: =D53/C53 -> 26.372102 | L53: =E53/C53 -> 27.372102 | M53: =F53/C53 -> 25.722683 | N53: =E53/F53 -> 1.0641231 | O53: =E53/H53 -> 16.594996 | P53: =E53/I53 -> 4.6026224 | Q53: =AVERAGE(M44:M55) -> 25.543579
A54: ='raw data'!A702 -> 2004-11 | B54: ='raw data'!U702 -> 680706.3 | C54: ='raw data'!V702 -> 287768.8 | D54: =E54-C54 -> 7721897.7 | E54: ='raw data'!AH702 -> 8009666.5 | F54: ='raw data'!AO702 -> 7537779.5 | G54: ='raw data'!AS702 -> 6313141.4 | H54: =E54-F54 -> 471887 | I54: =E54-G54 -> 1696525.1 | J54: =C54/E54*100 -> 3.5927688 | K54: =D54/C54 -> 26.833686 | L54: =E54/C54 -> 27.833686 | M54: =F54/C54 -> 26.193873 | N54: =E54/F54 -> 1.0626029 | O54: =E54/H54 -> 16.973696 | P54: =E54/I54 -> 4.721219
A55: ='raw data'!A703 -> 2004-12 | B55: ='raw data'!U703 -> 691415 | C55: ='raw data'!V703 -> 296868.7 | D55: =E55-C55 -> 7742069.1 | E55: ='raw data'!AH703 -> 8038937.8 | F55: ='raw data'!AO703 -> 7548653.1 | G55: ='raw data'!AS703 -> 6358149.7 | H55: =E55-F55 -> 490284.7 | I55: =E55-G55 -> 1680788.1 | J55: =C55/E55*100 -> 3.6928846 | K55: =D55/C55 -> 26.079102 | L55: =E55/C55 -> 27.079102 | M55: =F55/C55 -> 25.427582 | N55: =E55/F55 -> 1.06495 | O55: =E55/H55 -> 16.396469 | P55: =E55/I55 -> 4.7828384
A56: ='raw data'!A704 -> 2005-01 | B56: ='raw data'!U704 -> 693794.9 | C56: ='raw data'!V704 -> 303790.4 | D56: =E56-C56 -> 7792052.7 | E56: ='raw data'!AH704 -> 8095843.1 | F56: ='raw data'!AO704 -> 7607596.5 | G56: ='raw data'!AS704 -> 6424894.4 | H56: =E56-F56 -> 488246.6 | I56: =E56-G56 -> 1670948.7 | J56: =C56/E56*100 -> 3.7524245 | K56: =D56/C56 -> 25.649437 | L56: =E56/C56 -> 26.649437 | M56: =F56/C56 -> 25.042254 | N56: =E56/F56 -> 1.0641788 | O56: =E56/H56 -> 16.581463 | P56: =E56/I56 -> 4.8450578
A57: ='raw data'!A705 -> 2005-02 | B57: ='raw data'!U705 -> 690746.4 | C57: ='raw data'!V705 -> 299128.9 | D57: =E57-C57 -> 7874900.6 | E57: ='raw data'!AH705 -> 8174029.5 | F57: ='raw data'!AO705 -> 7661914 | G57: ='raw data'!AS705 -> 6462188.8 | H57: =E57-F57 -> 512115.5 | I57: =E57-G57 -> 1711840.7 | J57: =C57/E57*100 -> 3.6595036 | K57: =D57/C57 -> 26.326111 | L57: =E57/C57 -> 27.326111 | M57: =F57/C57 -> 25.614088 | N57: =E57/F57 -> 1.0668391 | O57: =E57/H57 -> 15.961301 | P57: =E57/I57 -> 4.7749943
A58: ='raw data'!A706 -> 2005-03 | B58: ='raw data'!U706 -> 693057.9 | C58: ='raw data'!V706 -> 299727.2 | D58: =E58-C58 -> 7968888.7 | E58: ='raw data'!AH706 -> 8268615.9 | F58: ='raw data'!AO706 -> 7746512.2 | G58: ='raw data'!AS706 -> 6499953.9 | H58: =E58-F58 -> 522103.7 | I58: =E58-G58 -> 1768662 | J58: =C58/E58*100 -> 3.6248775 | K58: =D58/C58 -> 26.587139 | L58: =E58/C58 -> 27.587139 | M58: =F58/C58 -> 25.845209 | N58: =E58/F58 -> 1.0673986 | O58: =E58/H58 -> 15.837114 | P58: =E58/I58 -> 4.6750684
A59: ='raw data'!A707 -> 2005-04 | B59: ='raw data'!U707 -> 693525.3 | C59: ='raw data'!V707 -> 301125.6 | D59: =E59-C59 -> 7999630.4 | E59: ='raw data'!AH707 -> 8300756 | F59: ='raw data'!AO707 -> 7765176.6 | G59: ='raw data'!AS707 -> 6572787.5 | H59: =E59-F59 -> 535579.4 | I59: =E59-G59 -> 1727968.5 | J59: =C59/E59*100 -> 3.6276889 | K59: =D59/C59 -> 26.56576 | L59: =E59/C59 -> 27.56576 | M59: =F59/C59 -> 25.787169 | N59: =E59/F59 -> 1.068972 | O59: =E59/H59 -> 15.498647 | P59: =E59/I59 -> 4.8037658
A60: ='raw data'!A708 -> 2005-05 | B60: ='raw data'!U708 -> 691829.1 | C60: ='raw data'!V708 -> 298997.3 | D60: =E60-C60 -> 8081607.6 | E60: ='raw data'!AH708 -> 8380604.9 | F60: ='raw data'!AO708 -> 7834926.4 | G60: ='raw data'!AS708 -> 6603902.7 | H60: =E60-F60 -> 545678.5 | I60: =E60-G60 -> 1776702.2 | J60: =C60/E60*100 -> 3.5677293 | K60: =D60/C60 -> 27.029032 | L60: =E60/C60 -> 28.029032 | M60: =F60/C60 -> 26.204004 | N60: =E60/F60 -> 1.0696469 | O60: =E60/H60 -> 15.358137 | P60: =E60/I60 -> 4.7169441
A61: ='raw data'!A709 -> 2005-06 | B61: ='raw data'!U709 -> 692900.4 | C61: ='raw data'!V709 -> 301594.9 | D61: =E61-C61 -> 8126343.4 | E61: ='raw data'!AH709 -> 8427938.3 | F61: ='raw data'!AO709 -> 7877526.3 | G61: ='raw data'!AS709 -> 6690853.8 | H61: =E61-F61 -> 550412 | I61: =E61-G61 -> 1737084.5 | J61: =C61/E61*100 -> 3.5785134 | K61: =D61/C61 -> 26.944565 | L61: =E61/C61 -> 27.944565 | M61: =F61/C61 -> 26.119561 | N61: =E61/F61 -> 1.0698712 | O61: =E61/H61 -> 15.312054 | P61: =E61/I61 -> 4.8517722
A62: ='raw data'!A710 -> 2005-07 | B62: ='raw data'!U710 -> 697638.4 | C62: ='raw data'!V710 -> 302440.1 | D62: =E62-C62 -> 8171457.1 | E62: ='raw data'!AH710 -> 8473897.2 | F62: ='raw data'!AO710 -> 7939848.9 | G62: ='raw data'!AS710 -> 6730293.7 | H62: =E62-F62 -> 534048.3 | I62: =E62-G62 -> 1743603.5 | J62: =C62/E62*100 -> 3.5690792 | K62: =D62/C62 -> 27.018431 | L62: =E62/C62 -> 28.018431 | M62: =F62/C62 -> 26.252633 | N62: =E62/F62 -> 1.0672618 | O62: =E62/H62 -> 15.867286 | P62: =E62/I62 -> 4.8599909
A63: ='raw data'!A711 -> 2005-08 | B63: ='raw data'!U711 -> 705855.3 | C63: ='raw data'!V711 -> 302007.9 | D63: =E63-C63 -> 8269716.8 | E63: ='raw data'!AH711 -> 8571724.7 | F63: ='raw data'!AO711 -> 8032491.9 | G63: ='raw data'!AS711 -> 6832019.6 | H63: =E63-F63 -> 539232.8 | I63: =E63-G63 -> 1739705.1 | J63: =C63/E63*100 -> 3.5233038 | K63: =D63/C63 -> 27.382452 | L63: =E63/C63 -> 28.382452 | M63: =F63/C63 -> 26.59696 | N63: =E63/F63 -> 1.0671314 | O63: =E63/H63 -> 15.896149 | P63: =E63/I63 -> 4.9271136
A64: ='raw data'!A712 -> 2005-09 | B64: ='raw data'!U712 -> 711058.5 | C64: ='raw data'!V712 -> 304130.3 | D64: =E64-C64 -> 8329633.9 | E64: ='raw data'!AH712 -> 8633764.2 | F64: ='raw data'!AO712 -> 8075420.7 | G64: ='raw data'!AS712 -> 6892137.5 | H64: =E64-F64 -> 558343.5 | I64: =E64-G64 -> 1741626.7 | J64: =C64/E64*100 -> 3.522569 | K64: =D64/C64 -> 27.388372 | L64: =E64/C64 -> 28.388372 | M64: =F64/C64 -> 26.552503 | N64: =E64/F64 -> 1.0691411 | O64: =E64/H64 -> 15.463177 | P64: =E64/I64 -> 4.9572989
A65: ='raw data'!A713 -> 2005-10 | B65: ='raw data'!U713 -> 702515.5 | C65: ='raw data'!V713 -> 296316.6 | D65: =E65-C65 -> 8376140.3 | E65: ='raw data'!AH713 -> 8672456.9 | F65: ='raw data'!AO713 -> 8114409.2 | G65: ='raw data'!AS713 -> 6932267.9 | H65: =E65-F65 -> 558047.7 | I65: =E65-G65 -> 1740189 | J65: =C65/E65*100 -> 3.4167549 | K65: =D65/C65 -> 28.267536 | L65: =E65/C65 -> 29.267536 | M65: =F65/C65 -> 27.384255 | N65: =E65/F65 -> 1.0687724 | O65: =E65/H65 -> 15.540709 | P65: =E65/I65 -> 4.9836293
... A261: ='raw data'!A909 -> 2022-02 | B261: ='raw data'!U909 -> 1680648.9 | C261: ='raw data'!V909 -> 820644.5 | D261: =E261-C261 -> 21842259 | E261: ='raw data'!AH909 -> 22662904 | F261: ='raw data'!AO909 -> 20681666 | G261: ='raw data'!AS909 -> 36246796 | H261: =E261-F261 -> 1981237 | I261: =E261-G261 -> -13583893 | J261: =C261/E261*100 -> 3.6210916 | K261: =D261/C261 -> 26.615982 | L261: =E261/C261 -> 27.615982 | M261: =F261/C261 -> 25.201737 | N261: =E261/F261 -> 1.0957968 | O261: =E261/H261 -> 11.438765 | P261: =E261/I261 -> -1.6683659

Sheet results_new
A1: Time | B1: Consumer Credit | C1: Credit Card | D1: Other Asset | E1: Total Asset | F1: Deposits | G1: Total Liability | H1: Residual (NW) | I1: Net Worth | J1: Deposits / CC | K1: CC / TA | L1: OA / CC | M1: TA / CC | N1: TL / CC | O1: TA / TL | P1: TA / Deposits | Q1: TA / NW
A2: ='raw data'!A650 -> 2000-07 | B2: ='raw data'!U650 -> 531142 | C2: ='raw data'!V650 -> 211897.8 | D2: =E2-C2 -> 5693184 | E2: ='raw data'!AH650 -> 5905081.8 | F2: =SUM('raw data'!AI650:AK650) -> 4521704.5 | G2: ='raw data'!AO650 -> 5678886 | H2: =E2-G2 -> 226195.8 | I2: =E2-F2 -> 1383377.3 | J2: =F2/C2 -> 21.339082 | K2: =C2/E2 -> 0.035883974 | L2: =D2/C2 -> 26.867594 | M2: =E2/C2 -> 27.867594 | N2: =G2/C2 -> 26.800118 | O2: =E2/G2 -> 1.039831 | P2: =E2/F2 -> 1.3059416 | Q2: =E2/I2 -> 4.2685982
A3: ='raw data'!A651 -> 2000-08 | B3: ='raw data'!U651 -> 538855.4 | C3: ='raw data'!V651 -> 217854 | D3: =E3-C3 -> 5716299.2 | E3: ='raw data'!AH651 -> 5934153.2 | F3: =SUM('raw data'!AI651:AK651) -> 4564306.7 | G3: ='raw data'!AO651 -> 5714051.1 | H3: =E3-G3 -> 220102.1 | I3: =E3-F3 -> 1369846.5 | J3: =F3/C3 -> 20.951218 | K3: =C3/E3 -> 0.036711893 | L3: =D3/C3 -> 26.239129 | M3: =E3/C3 -> 27.239129 | N3: =G3/C3 -> 26.22881 | O3: =E3/G3 -> 1.0385194 | P3: =E3/F3 -> 1.3001215 | Q3: =E3/I3 -> 4.3319841
A4: ='raw data'!A652 -> 2000-09 | B4: ='raw data'!U652 -> 543717.1 | C4: ='raw data'!V652 -> 222410.9 | D4: =E4-C4 -> 5751305.6 | E4: ='raw data'!AH652 -> 5973716.5 | F4: =SUM('raw data'!AI652:AK652) -> 4578304.4 | G4: ='raw data'!AO652 -> 5736376.6 | H4: =E4-G4 -> 237339.9 | I4: =E4-F4 -> 1395412.1 | J4: =F4/C4 -> 20.584892 | K4: =C4/E4 -> 0.037231579 | L4: =D4/C4 -> 25.85892 | M4: =E4/C4 -> 26.85892 | N4: =G4/C4 -> 25.791796 | O4: =E4/G4 -> 1.0413745 | P4: =E4/F4 -> 1.304788 | Q4: =E4/I4 -> 4.2809694
A5: ='raw data'!A653 -> 2000-10 | B5: ='raw data'!U653 -> 544271.9 | C5: ='raw data'!V653 -> 220752.4 | D5: =E5-C5 -> 5770217.5 | E5: ='raw data'!AH653 -> 5990969.9 | F5: =SUM('raw data'!AI653:AK653) -> 4585167.3 | G5: ='raw data'!AO653 -> 5730192.1 | H5: =E5-G5 -> 260777.8 | I5: =E5-F5 -> 1405802.6 | J5: =F5/C5 -> 20.770634 | K5: =C5/E5 -> 0.036847523 | L5: =D5/C5 -> 26.138866 | M5: =E5/C5 -> 27.138866 | N5: =G5/C5 -> 25.957553 | O5: =E5/G5 -> 1.0455094 | P5: =E5/F5 -> 1.3065979 | Q5: =E5/I5 -> 4.2616011
A6: ='raw data'!A654 -> 2000-11 | B6: ='raw data'!U654 -> 548263.8 | C6: ='raw data'!V654 -> 222338.7 | D6: =E6-C6 -> 5768300.6 | E6: ='raw data'!AH654 -> 5990639.3 | F6: =SUM('raw data'!AI654:AK654) -> 4576630.5 | G6: ='raw data'!AO654 -> 5716039.2 | H6: =E6-G6 -> 274600.1 | I6: =E6-F6 -> 1414008.8 | J6: =F6/C6 -> 20.584048 | K6: =C6/E6 -> 0.037114353 | L6: =D6/C6 -> 25.943754 | M6: =E6/C6 -> 26.943754 | N6: =G6/C6 -> 25.708701 | O6: =E6/G6 -> 1.0480403 | P6: =E6/F6 -> 1.3089628 | Q6: =E6/I6 -> 4.2366351
A7: ='raw data'!A655 -> 2000-12 | B7: ='raw data'!U655 -> 555531.4 | C7: ='raw data'!V655 -> 228197.3 | D7: =E7-C7 -> 5839338.5 | E7: ='raw data'!AH655 -> 6067535.8 | F7: =SUM('raw data'!AI655:AK655) -> 4646582.5 | G7: ='raw data'!AO655 -> 5809431.8 | H7: =E7-G7 -> 258104 | I7: =E7-F7 -> 1420953.3 | J7: =F7/C7 -> 20.362127 | K7: =C7/E7 -> 0.037609551 | L7: =D7/C7 -> 25.58899 | M7: =E7/C7 -> 26.58899 | N7: =G7/C7 -> 25.457934 | O7: =E7/G7 -> 1.0444284 | P7: =E7/F7 -> 1.3058061 | Q7: =E7/I7 -> 4.2700459
A8: ='raw data'!A656 -> 2001-01 | B8: ='raw data'!U656 -> 558590.1 | C8: ='raw data'!V656 -> 230967.4 | D8: =E8-C8 -> 5920051.7 | E8: ='raw data'!AH656 -> 6151019.1 | F8: =SUM('raw data'!AI656:AK656) -> 4688421.9 | G8: ='raw data'!AO656 -> 5877247 | H8: =E8-G8 -> 273772.1 | I8: =E8-F8 -> 1462597.2 | J8: =F8/C8 -> 20.299063 | K8: =C8/E8 -> 0.037549453 | L8: =D8/C8 -> 25.631547 | M8: =E8/C8 -> 26.631547 | N8: =G8/C8 -> 25.446219 | O8: =E8/G8 -> 1.0465817 | P8: =E8/F8 -> 1.3119594 | Q8: =E8/I8 -> 4.2055455
A9: ='raw data'!A657 -> 2001-02 | B9: ='raw data'!U657 -> 557858 | C9: ='raw data'!V657 -> 229551.1 | D9: =E9-C9 -> 5908417.3 | E9: ='raw data'!AH657 -> 6137968.4 | F9: =SUM('raw data'!AI657:AK657) -> 4700436.3 | G9: ='raw data'!AO657 -> 5870782.7 | H9: =E9-G9 -> 267185.7 | I9: =E9-F9 -> 1437532.1 | J9: =F9/C9 -> 20.476645 | K9: =C9/E9 -> 0.037398547 | L9: =D9/C9 -> 25.739007 | M9: =E9/C9 -> 26.739007 | N9: =G9/C9 -> 25.575058 | O9: =E9/G9 -> 1.0455111 | P9: =E9/F9 -> 1.3058295 | Q9: =E9/I9 -> 4.2697957
A10: ='raw data'!A658 -> 2001-03 | B10: ='raw data'!U658 -> 557205.5 | C10: ='raw data'!V658 -> 228144.8 | D10: =E10-C10 -> 5960646.7 | E10: ='raw data'!AH658 -> 6188791.5 | F10: =SUM('raw data'!AI658:AK658) -> 4737073.4 | G10: ='raw data'!AO658 -> 5919212.6 | H10: =E10-G10 -> 269578.9 | I10: =E10-F10 -> 1451718.1 | J10: =F10/C10 -> 20.763451 | K10: =C10/E10 -> 0.036864192 | L10: =D10/C10 -> 26.126595 | M10: =E10/C10 -> 27.126595 | N10: =G10/C10 -> 25.944981 | O10: =E10/G10 -> 1.045543 | P10: =E10/F10 -> 1.3064589 | Q10: =E10/I10 -> 4.2630808
A11: ='raw data'!A659 -> 2001-04 | B11: ='raw data'!U659 -> 561350.2 | C11: ='raw data'!V659 -> 232200.8 | D11: =E11-C11 -> 5996841.9 | E11: ='raw data'!AH659 -> 6229042.7 | F11: =SUM('raw data'!AI659:AK659) -> 4783168.3 | G11: ='raw data'!AO659 -> 5948783.7 | H11: =E11-G11 -> 280259 | I11: =E11-F11 -> 1445874.4 | J11: =F11/C11 -> 20.599276 | K11: =C11/E11 -> 0.037277124 | L11: =D11/C11 -> 25.826104 | M11: =E11/C11 -> 26.826104 | N11: =G11/C11 -> 25.619135 | O11: =E11/G11 -> 1.047112 | P11: =E11/F11 -> 1.3022838 | Q11: =E11/I11 -> 4.3081492
A12: ='raw data'!A660 -> 2001-05 | B12: ='raw data'!U660 -> 566114.6 | C12: ='raw data'!V660 -> 235574.1 | D12: =E12-C12 -> 5983711.3 | E12: ='raw data'!AH660 -> 6219285.4 | F12: =SUM('raw data'!AI660:AK660) -> 4814665.4 | G12: ='raw data'!AO660 -> 5946266.5 | H12: =E12-G12 -> 273018.9 | I12: =E12-F12 -> 1404620 | J12: =F12/C12 -> 20.438008 | K12: =C12/E12 -> 0.037878001 | L12: =D12/C12 -> 25.400548 | M12: =E12/C12 -> 26.400548 | N12: =G12/C12 -> 25.241597 | O12: =E12/G12 -> 1.0459143 | P12: =E12/F12 -> 1.2917378 | Q12: =E12/I12 -> 4.4277352
A13: ='raw data'!A661 -> 2001-06 | B13: ='raw data'!U661 -> 564557.4 | C13: ='raw data'!V661 -> 233267.1 | D13: =E13-C13 -> 5974287.5 | E13: ='raw data'!AH661 -> 6207554.6 | F13: =SUM('raw data'!AI661:AK661) -> 4833647.1 | G13: ='raw data'!AO661 -> 5932611.4 | H13: =E13-G13 -> 274943.2 | I13: =E13-F13 -> 1373907.5 | J13: =F13/C13 -> 20.721512 | K13: =C13/E13 -> 0.037577938 | L13: =D13/C13 -> 25.611359 | M13: =E13/C13 -> 26.611359 | N13: =G13/C13 -> 25.432697 | O13: =E13/G13 -> 1.0463444 | P13: =E13/F13 -> 1.2842383 | Q13: =E13/I13 -> 4.5181751
... A43: ='raw data'!A691 -> 2003-12 | B43: ='raw data'!U691 -> 664772.1 | C43: ='raw data'!V691 -> 280989.7 | D43: =E43-C43 -> 7033550.5 | E43: ='raw data'!AH691 -> 7314540.2 | F43: =SUM('raw data'!AI691:AK691) -> 5631953.6 | G43: ='raw data'!AO691 -> 6930551.9 | H43: =E43-G43 -> 383988.3 | I43: =E43-F43 -> 1682586.6 | J43: =F43/C43 -> 20.043274 | K43: =C43/E43 -> 0.038415224 | L43: =D43/C43 -> 25.031346 | M43: =E43/C43 -> 26.031346 | N43: =G43/C43 -> 24.66479 | O43: =E43/G43 -> 1.0554052 | P43: =E43/F43 -> 1.2987572 | Q43: =E43/I43 -> 4.3471998
A44: ='raw data'!A692 -> 2004-01 | B44: ='raw data'!U692 -> 671934.4 | C44: ='raw data'!V692 -> 283276.6 | D44: =E44-C44 -> 7118876.4 | E44: ='raw data'!AH692 -> 7402153 | F44: =SUM('raw data'!AI692:AK692) -> 5684357.4 | G44: ='raw data'!AO692 -> 7023084 | H44: =E44-G44 -> 379069 | I44: =E44-F44 -> 1717795.6 | J44: =F44/C44 -> 20.066456 | K44: =C44/E44 -> 0.038269487 | L44: =D44/C44 -> 25.130478 | M44: =E44/C44 -> 26.130478 | N44: =G44/C44 -> 24.79232 | O44: =E44/G44 -> 1.0539747 | P44: =E44/F44 -> 1.302197 | Q44: =E44/I44 -> 4.3091 | S44: Avg TA/D | T44: Avg TA/NW
A45: ='raw data'!A693 -> 2004-02 | B45: ='raw data'!U693 -> 671297.8 | C45: ='raw data'!V693 -> 281560.2 | D45: =E45-C45 -> 7239054.6 | E45: ='raw data'!AH693 -> 7520614.8 | F45: =SUM('raw data'!AI693:AK693) -> 5749278.9 | G45: ='raw data'!AO693 -> 7130441.1 | H45: =E45-G45 -> 390173.7 | I45: =E45-F45 -> 1771335.9 | J45: =F45/C45 -> 20.419359 | K45: =C45/E45 -> 0.037438455 | L45: =D45/C45 -> 25.710504 | M45: =E45/C45 -> 26.710504 | N45: =G45/C45 -> 25.324748 | O45: =E45/G45 -> 1.0547194 | P45: =E45/F45 -> 1.3080971 | Q45: =E45/I45 -> 4.2457305 | R45: 2004 | S45: =AVERAGE(P44:P55) -> 1.2835543 | T45: =AVERAGE(Q44:Q55) -> 4.5341847
A46: ='raw data'!A694 -> 2004-03 | B46: ='raw data'!U694 -> 669655.6 | C46: ='raw data'!V694 -> 279474.5 | D46: =E46-C46 -> 7272080.8 | E46: ='raw data'!AH694 -> 7551555.3 | F46: =SUM('raw data'!AI694:AK694) -> 5828558.8 | G46: ='raw data'!AO694 -> 7160907.1 | H46: =E46-G46 -> 390648.2 | I46: =E46-F46 -> 1722996.5 | J46: =F46/C46 -> 20.855423 | K46: =C46/E46 -> 0.037008866 | L46: =D46/C46 -> 26.020552 | M46: =E46/C46 -> 27.020552 | N46: =G46/C46 -> 25.622757 | O46: =E46/G46 -> 1.0545529 | P46: =E46/F46 -> 1.2956128 | Q46: =E46/I46 -> 4.3828036 | R46: 2005 | S46: =AVERAGE(P56:P67) -> 1.258781 | T46: =AVERAGE(Q56:Q67) -> 4.8672367
A47: ='raw data'!A695 -> 2004-04 | B47: ='raw data'!U695 -> 672082.9 | C47: ='raw data'!V695 -> 281049.1 | D47: =E47-C47 -> 7357249.4 | E47: ='raw data'!AH695 -> 7638298.5 | F47: =SUM('raw data'!AI695:AK695) -> 5891009 | G47: ='raw data'!AO695 -> 7202602.1 | H47: =E47-G47 -> 435696.4 | I47: =E47-F47 -> 1747289.5 | J47: =F47/C47 -> 20.960782 | K47: =C47/E47 -> 0.036794726 | L47: =D47/C47 -> 26.177808 | M47: =E47/C47 -> 27.177808 | N47: =G47/C47 -> 25.627558 | O47: =E47/G47 -> 1.0604915 | P47: =E47/F47 -> 1.2966028 | Q47: =E47/I47 -> 4.3715128 | R47: 2006 | S47: =AVERAGE(P68:P79) -> 1.2443974 | T47: =AVERAGE(Q68:Q79) -> 5.0934118
A48: ='raw data'!A696 -> 2004-05 | B48: ='raw data'!U696 -> 677176.8 | C48: ='raw data'!V696 -> 284903.9 | D48: =E48-C48 -> 7379888.4 | E48: ='raw data'!AH696 -> 7664792.3 | F48: =SUM('raw data'!AI696:AK696) -> 6000669.7 | G48: ='raw data'!AO696 -> 7233687.2 | H48: =E48-G48 -> 431105.1 | I48: =E48-F48 -> 1664122.6 | J48: =F48/C48 -> 21.062083 | K48: =C48/E48 -> 0.037170466 | L48: =D48/C48 -> 25.90308 | M48: =E48/C48 -> 26.90308 | N48: =G48/C48 -> 25.38992 | O48: =E48/G48 -> 1.0595969 | P48: =E48/F48 -> 1.2773228 | Q48: =E48/I48 -> 4.605906
A49: ='raw data'!A697 -> 2004-06 | B49: ='raw data'!U697 -> 679977.5 | C49: ='raw data'!V697 -> 287433.6 | D49: =E49-C49 -> 7454905.4 | E49: ='raw data'!AH697 -> 7742339 | F49: =SUM('raw data'!AI697:AK697) -> 6060581.5 | G49: ='raw data'!AO697 -> 7331544.1 | H49: =E49-G49 -> 410794.9 | I49: =E49-F49 -> 1681757.5 | J49: =F49/C49 -> 21.085153 | K49: =C49/E49 -> 0.037124905 | L49: =D49/C49 -> 25.936096 | M49: =E49/C49 -> 26.936096 | N49: =G49/C49 -> 25.506914 | O49: =E49/G49 -> 1.0560312 | P49: =E49/F49 -> 1.2774911 | Q49: =E49/I49 -> 4.603719
A50: ='raw data'!A698 -> 2004-07 | B50: ='raw data'!U698 -> 680087 | C50: ='raw data'!V698 -> 287878.6 | D50: =E50-C50 -> 7557867.1 | E50: ='raw data'!AH698 -> 7845745.7 | F50: =SUM('raw data'!AI698:AK698) -> 6156965.3 | G50: ='raw data'!AO698 -> 7433368.8 | H50: =E50-G50 -> 412376.9 | I50: =E50-F50 -> 1688780.4 | J50: =F50/C50 -> 21.387367 | K50: =C50/E50 -> 0.036692318 | L50: =D50/C50 -> 26.253661 | M50: =E50/C50 -> 27.253661 | N50: =G50/C50 -> 25.821193 | O50: =E50/G50 -> 1.0554764 | P50: =E50/F50 -> 1.2742878 | Q50: =E50/I50 -> 4.6458058 | S50: Avg D/CC | T50: Avg CC/TA
A51: ='raw data'!A699 -> 2004-08 | B51: ='raw data'!U699 -> 683613.5 | C51: ='raw data'!V699 -> 290661.3 | D51: =E51-C51 -> 7586471.1 | E51: ='raw data'!AH699 -> 7877132.4 | F51: =SUM('raw data'!AI699:AK699) -> 6169053.8 | G51: ='raw data'!AO699 -> 7445370.8 | H51: =E51-G51 -> 431761.6 | I51: =E51-F51 -> 1708078.6 | J51: =F51/C51 -> 21.224201 | K51: =C51/E51 -> 0.03689938 | L51: =D51/C51 -> 26.100727 | M51: =E51/C51 -> 27.100727 | N51: =G51/C51 -> 25.615281 | O51: =E51/G51 -> 1.0579906 | P51: =E51/F51 -> 1.2768785 | Q51: =E51/I51 -> 4.611692 | S51: =AVERAGE(J8:J55) -> 21.292136 | T51: =AVERAGE(K8:K55) -> 0.036700477
A52: ='raw data'!A700 -> 2004-09 | B52: ='raw data'!U700 -> 686419.5 | C52: ='raw data'!V700 -> 294299.2 | D52: =E52-C52 -> 7666584.1 | E52: ='raw data'!AH700 -> 7960883.3 | F52: =SUM('raw data'!AI700:AK700) -> 6202452.8 | G52: ='raw data'!AO700 -> 7498189.3 | H52: =E52-G52 -> 462694 | I52: =E52-F52 -> 1758430.5 | J52: =F52/C52 -> 21.07533 | K52: =C52/E52 -> 0.036968159 | L52: =D52/C52 -> 26.050306 | M52: =E52/C52 -> 27.050306 | N52: =G52/C52 -> 25.478116 | O52: =E52/G52 -> 1.0617074 | P52: =E52/F52 -> 1.2835057 | Q52: =E52/I52 -> 4.5272664
A53: ='raw data'!A701 -> 2004-10 | B53: ='raw data'!U701 -> 684346.8 | C53: ='raw data'!V701 -> 291309 | D53: =E53-C53 -> 7682430.6 | E53: ='raw data'!AH701 -> 7973739.6 | F53: =SUM('raw data'!AI701:AK701) -> 6241305.6 | G53: ='raw data'!AO701 -> 7493249 | H53: =E53-G53 -> 480490.6 | I53: =E53-F53 -> 1732434 | J53: =F53/C53 -> 21.425035 | K53: =C53/E53 -> 0.036533548 | L53: =D53/C53 -> 26.372102 | M53: =E53/C53 -> 27.372102 | N53: =G53/C53 -> 25.722683 | O53: =E53/G53 -> 1.0641231 | P53: =E53/F53 -> 1.2775756 | Q53: =E53/I53 -> 4.6026224
A54: ='raw data'!A702 -> 2004-11 | B54: ='raw data'!U702 -> 680706.3 | C54: ='raw data'!V702 -> 287768.8 | D54: =E54-C54 -> 7721897.7 | E54: ='raw data'!AH702 -> 8009666.5 | F54: =SUM('raw data'!AI702:AK702) -> 6313141.4 | G54: ='raw data'!AO702 -> 7537779.5 | H54: =E54-G54 -> 471887 | I54: =E54-F54 -> 1696525.1 | J54: =F54/C54 -> 21.938241 | K54: =C54/E54 -> 0.035927688 | L54: =D54/C54 -> 26.833686 | M54: =E54/C54 -> 27.833686 | N54: =G54/C54 -> 26.193873 | O54: =E54/G54 -> 1.0626029 | P54: =E54/F54 -> 1.2687291 | Q54: =E54/I54 -> 4.721219
A55: ='raw data'!A703 -> 2004-12 | B55: ='raw data'!U703 -> 691415 | C55: ='raw data'!V703 -> 296868.7 | D55: =E55-C55 -> 7742069.1 | E55: ='raw data'!AH703 -> 8038937.8 | F55: =SUM('raw data'!AI703:AK703) -> 6358149.7 | G55: ='raw data'!AO703 -> 7548653.1 | H55: =E55-G55 -> 490284.7 | I55: =E55-F55 -> 1680788.1 | J55: =F55/C55 -> 21.41738 | K55: =C55/E55 -> 0.036928846 | L55: =D55/C55 -> 26.079102 | M55: =E55/C55 -> 27.079102 | N55: =G55/C55 -> 25.427582 | O55: =E55/G55 -> 1.06495 | P55: =E55/F55 -> 1.2643518 | Q55: =E55/I55 -> 4.7828384
A56: ='raw data'!A704 -> 2005-01 | B56: ='raw data'!U704 -> 693794.9 | C56: ='raw data'!V704 -> 303790.4 | D56: =E56-C56 -> 7792052.7 | E56: ='raw data'!AH704 -> 8095843.1 | F56: =SUM('raw data'!AI704:AK704) -> 6424894.4 | G56: ='raw data'!AO704 -> 7607596.5 | H56: =E56-G56 -> 488246.6 | I56: =E56-F56 -> 1670948.7 | J56: =F56/C56 -> 21.149103 | K56: =C56/E56 -> 0.037524245 | L56: =D56/C56 -> 25.649437 | M56: =E56/C56 -> 26.649437 | N56: =G56/C56 -> 25.042254 | O56: =E56/G56 -> 1.0641788 | P56: =E56/F56 -> 1.2600741 | Q56: =E56/I56 -> 4.8450578
A57: ='raw data'!A705 -> 2005-02 | B57: ='raw data'!U705 -> 690746.4 | C57: ='raw data'!V705 -> 299128.9 | D57: =E57-C57 -> 7874900.6 | E57: ='raw data'!AH705 -> 8174029.5 | F57: =SUM('raw data'!AI705:AK705) -> 6462188.8 | G57: ='raw data'!AO705 -> 7661914 | H57: =E57-G57 -> 512115.5 | I57: =E57-F57 -> 1711840.7 | J57: =F57/C57 -> 21.603358 | K57: =C57/E57 -> 0.036595036 | L57: =D57/C57 -> 26.326111 | M57: =E57/C57 -> 27.326111 | N57: =G57/C57 -> 25.614088 | O57: =E57/G57 -> 1.0668391 | P57: =E57/F57 -> 1.2649011 | Q57: =E57/I57 -> 4.7749943
A58: ='raw data'!A706 -> 2005-03 | B58: ='raw data'!U706 -> 693057.9 | C58: ='raw data'!V706 -> 299727.2 | D58: =E58-C58 -> 7968888.7 | E58: ='raw data'!AH706 -> 8268615.9 | F58: =SUM('raw data'!AI706:AK706) -> 6499953.9 | G58: ='raw data'!AO706 -> 7746512.2 | H58: =E58-G58 -> 522103.7 | I58: =E58-F58 -> 1768662 | J58: =F58/C58 -> 21.686233 | K58: =C58/E58 -> 0.036248775 | L58: =D58/C58 -> 26.587139 | M58: =E58/C58 -> 27.587139 | N58: =G58/C58 -> 25.845209 | O58: =E58/G58 -> 1.0673986 | P58: =E58/F58 -> 1.2721038 | Q58: =E58/I58 -> 4.6750684
A59: ='raw data'!A707 -> 2005-04 | B59: ='raw data'!U707 -> 693525.3 | C59: ='raw data'!V707 -> 301125.6 | D59: =E59-C59 -> 7999630.4 | E59: ='raw data'!AH707 -> 8300756 | F59: =SUM('raw data'!AI707:AK707) -> 6572787.5 | G59: ='raw data'!AO707 -> 7765176.6 | H59: =E59-G59 -> 535579.4 | I59: =E59-F59 -> 1727968.5 | J59: =F59/C59 -> 21.827395 | K59: =C59/E59 -> 0.036276889 | L59: =D59/C59 -> 26.56576 | M59: =E59/C59 -> 27.56576 | N59: =G59/C59 -> 25.787169 | O59: =E59/G59 -> 1.068972 | P59: =E59/F59 -> 1.2628974 | Q59: =E59/I59 -> 4.8037658
A60: ='raw data'!A708 -> 2005-05 | B60: ='raw data'!U708 -> 691829.1 | C60: ='raw data'!V708 -> 298997.3 | D60: =E60-C60 -> 8081607.6 | E60: ='raw data'!AH708 -> 8380604.9 | F60: =SUM('raw data'!AI708:AK708) -> 6603902.7 | G60: ='raw data'!AO708 -> 7834926.4 | H60: =E60-G60 -> 545678.5 | I60: =E60-F60 -> 1776702.2 | J60: =F60/C60 -> 22.086831 | K60: =C60/E60 -> 0.035677293 | L60: =D60/C60 -> 27.029032 | M60: =E60/C60 -> 28.029032 | N60: =G60/C60 -> 26.204004 | O60: =E60/G60 -> 1.0696469 | P60: =E60/F60 -> 1.2690382 | Q60: =E60/I60 -> 4.7169441
A61: ='raw data'!A709 -> 2005-06 | B61: ='raw data'!U709 -> 692900.4 | C61: ='raw data'!V709 -> 301594.9 | D61: =E61-C61 -> 8126343.4 | E61: ='raw data'!AH709 -> 8427938.3 | F61: =SUM('raw data'!AI709:AK709) -> 6690853.8 | G61: ='raw data'!AO709 -> 7877526.3 | H61: =E61-G61 -> 550412 | I61: =E61-F61 -> 1737084.5 | J61: =F61/C61 -> 22.184904 | K61: =C61/E61 -> 0.035785134 | L61: =D61/C61 -> 26.944565 | M61: =E61/C61 -> 27.944565 | N61: =G61/C61 -> 26.119561 | O61: =E61/G61 -> 1.0698712 | P61: =E61/F61 -> 1.2596208 | Q61: =E61/I61 -> 4.8517722
A62: ='raw data'!A710 -> 2005-07 | B62: ='raw data'!U710 -> 697638.4 | C62: ='raw data'!V710 -> 302440.1 | D62: =E62-C62 -> 8171457.1 | E62: ='raw data'!AH710 -> 8473897.2 | F62: =SUM('raw data'!AI710:AK710) -> 6730293.7 | G62: ='raw data'!AO710 -> 7939848.9 | H62: =E62-G62 -> 534048.3 | I62: =E62-F62 -> 1743603.5 | J62: =F62/C62 -> 22.253311 | K62: =C62/E62 -> 0.035690792 | L62: =D62/C62 -> 27.018431 | M62: =E62/C62 -> 28.018431 | N62: =G62/C62 -> 26.252633 | O62: =E62/G62 -> 1.0672618 | P62: =E62/F62 -> 1.259068 | Q62: =E62/I62 -> 4.8599909
A63: ='raw data'!A711 -> 2005-08 | B63: ='raw data'!U711 -> 705855.3 | C63: ='raw data'!V711 -> 302007.9 | D63: =E63-C63 -> 8269716.8 | E63: ='raw data'!AH711 -> 8571724.7 | F63: =SUM('raw data'!AI711:AK711) -> 6832019.6 | G63: ='raw data'!AO711 -> 8032491.9 | H63: =E63-G63 -> 539232.8 | I63: =E63-F63 -> 1739705.1 | J63: =F63/C63 -> 22.62199 | K63: =C63/E63 -> 0.035233038 | L63: =D63/C63 -> 27.382452 | M63: =E63/C63 -> 28.382452 | N63: =G63/C63 -> 26.59696 | O63: =E63/G63 -> 1.0671314 | P63: =E63/F63 -> 1.2546399 | Q63: =E63/I63 -> 4.9271136
... A261: ='raw data'!A909 -> 2022-02 | B261: ='raw data'!U909 -> 1680648.9 | C261: ='raw data'!V909 -> 820644.5 | D261: =E261-C261 -> 21842259 | E261: ='raw data'!AH909 -> 22662904 | F261: =SUM('raw data'!AI909:AK909) -> 36246796 | G261: ='raw data'!AO909 -> 20681666 | H261: =E261-G261 -> 1981237 | I261: =E261-F261 -> -13583893 | J261: =F261/C261 -> 44.168695 | K261: =C261/E261 -> 0.036210916 | L261: =D261/C261 -> 26.615982 | M261: =E261/C261 -> 27.615982 | N261: =G261/C261 -> 25.201737 | O261: =E261/G261 -> 1.0957968 | P261: =E261/F261 -> 0.6252388 | Q261: =E261/I261 -> -1.6683659
